Workbook

Sheet Cover
A1: APK6 - Washing Machine STM32 / Python GUI
A2: Software Requirements Specification (ASPICE SYS.2 / SWE.1 / SWE.6 traceability)
A4: Document ID | B4: APK6-SRS-001
A5: Version | B5: 1.1
A6: Date | B6: 2026-10-11
A7: Author | B7: M. Hanzouti
A8: Project | B8: f4_disco_rtos - RTOS training
A9: Target | B9: STM32F407G-DISC1, FreeRTOS
A10: Host | B10: Python 3.12, PyQt5, pyserial
A11: Based on | B11: APK5-SRS-001 (link layer)
A12: Document status | B12: Draft
A14: Revision history
A15: Version | B15: Date | C15: Author | D15: Change
A16: 1.0 | B16: 2026-10-10 | C16: M. Hanzouti | D16: Initial version
A17: 1.1 | B17: 2026-10-11 | C17: M. Hanzouti | D17: SystemTask IDLE/READY/RUN and SensorTask NO_ERROR/ERROR state machines; GET_STATUS format
A20: Sheets
A21: System Requirements | B21: SYS.2 - system requirements derived from the training goals.
A22: SW Requirements | B22: SWE.1 - software requirements, attributes, parent link, allocation, verification.
A23: Interface Spec | B23: Frame format, requests, events and status codes.
A24: SW Components | B24: SWE.2 - software architecture elements requirements are allocated to.
A25: Test Specification | B25: SWE.6 - test cases with expected results; Result column to fill in.
A26: Traceability | B26: SW requirement x test case matrix with coverage check.
A27: Dashboard | B27: Live counts: status, type, verification coverage, test results.
A29: Legend
A30: Yellow cells | B30: Editable attributes with a drop-down list (Status, Priority, Method, Result).
A31: 'shall' | B31: Mandatory requirement wording; one 'shall' per requirement.
A32: Status | B32: Draft > In review > Accepted (or Rejected / Deferred).
A33: Verification method | B33: Test, Analysis, Review, Inspection, Demonstration.

Sheet System Requirements
A1: System Requirements (SYS.2)
A2: APK6-SRS-001 | Version 1.1 | Stakeholder: RTOS training
A4: ID | B4: Title | C4: Requirement | D4: Type | E4: Rationale | F4: Priority | G4: Status | H4: Verification method | I4: # SW req linked
A5: SYS-REQ-001 | B5: Machine configuration | C5: The system shall allow the user to configure the wash program (Cotton, Synthetic, Wool, Quick), the temperature (20, 30, 40, 60, 90 C) and the spin speed (400 to 1400 rpm) from the PC GUI. | D5: Functional | E5: User sets up the wash before starting. | F5: High | G5: Accepted | H5: Test | I5: =COUNTIF('SW Requirements'!$F$5:$F$200,"*"&A5&"*") -> 6
A6: SYS-REQ-002 | B6: Start cycle | C6: The system shall allow the user to start a wash cycle from the PC GUI. | D6: Functional | E6: Main use case. | F6: High | G6: Accepted | H6: Test | I6: =COUNTIF('SW Requirements'!$F$5:$F$200,"*"&A6&"*") -> 3
A7: SYS-REQ-003 | B7: Cycle execution | C7: The STM32 shall run a wash cycle of 6 steps in the order Fill, Heat, Wash, Rinse, Drain, Spin, each step lasting 10 s. | D7: Functional | E7: Simulated washing machine sequence. | F7: High | G7: Accepted | H7: Test | I7: =COUNTIF('SW Requirements'!$F$5:$F$200,"*"&A7&"*") -> 4
A8: SYS-REQ-004 | B8: Real-time status | C8: The GUI shall display the current state, the current step and the progress of the cycle, updated at least every 200 ms. | D8: Performance | E8: User follows the cycle live. | F8: High | G8: Accepted | H8: Test | I8: =COUNTIF('SW Requirements'!$F$5:$F$200,"*"&A8&"*") -> 4
A9: SYS-REQ-005 | B9: Door open safety | C9: Opening the door (user button B1) during a cycle shall suspend the cycle immediately and the GUI shall display a 'door open' error. | D9: Functional | E9: Safety function of a washing machine. | F9: High | G9: Accepted | H9: Test | I9: =COUNTIF('SW Requirements'!$F$5:$F$200,"*"&A9&"*") -> 8
A10: SYS-REQ-006 | B10: Resume after door close | C10: Closing the door (next press of B1) shall resume the cycle from the step and progress where it was suspended. | D10: Functional | E10: No restart of the whole cycle. | F10: High | G10: Accepted | H10: Test | I10: =COUNTIF('SW Requirements'!$F$5:$F$200,"*"&A10&"*") -> 4
A11: SYS-REQ-007 | B11: Operating rules | C11: The STM32 shall refuse: a start without a complete configuration, a configuration or a start while a cycle is running or suspended, and a start with the door open. | D11: Functional | E11: Consistent machine behaviour, enforced by the target not by the GUI. | F11: High | G11: Accepted | H11: Test | I11: =COUNTIF('SW Requirements'!$F$5:$F$200,"*"&A11&"*") -> 8
A12: SYS-REQ-008 | B12: Communication interface | C12: PC and STM32 shall communicate with 3-byte frames SOF 0xAA - CMD - DATA over UART 115200 8N1: requests answered with CMD|0x80, and spontaneous events from the STM32. | D12: Interface | E12: Reuse of the APK5 link layer. | F12: High | G12: Accepted | H12: Test | I12: =COUNTIF('SW Requirements'!$F$5:$F$200,"*"&A12&"*") -> 8
A13: SYS-REQ-009 | B13: Board indication | C13: The board LEDs shall show: running (green blinking), configuration valid (orange), door open (red), cycle finished (blue). | D13: Functional | E13: Feedback without the PC. | F13: High | G13: Accepted | H13: Test | I13: =COUNTIF('SW Requirements'!$F$5:$F$200,"*"&A13&"*") -> 3
A14: SYS-REQ-010 | B14: Link robustness | C14: The link shall recover without reset from noise, lost bytes and partial frames. | D14: Non-functional | E14: Inherited from APK5. | F14: High | G14: Accepted | H14: Test | I14: =COUNTIF('SW Requirements'!$F$5:$F$200,"*"&A14&"*") -> 1
A15: SYS-REQ-011 | B15: Training without hardware | C15: The PC application shall offer a simulated board with the same behaviour as the firmware. | D15: Functional | E15: Trainees can work without a Discovery board. | F15: High | G15: Accepted | H15: Test | I15: =COUNTIF('SW Requirements'!$F$5:$F$200,"*"&A15&"*") -> 1

Sheet SW Requirements
A1: Software Requirements (SWE.1)
A2: APK6-SRS-001 | Version 1.1 | Parent: System Requirements | Allocation: SW Components
A4: ID | B4: Title | C4: Requirement | D4: Type | E4: SW component (SWE.2) | F4: Parent SYS req | G4: Rationale | H4: Priority | I4: Status | J4: Verification method | K4: Acceptance criteria | L4: Test case(s) (SWE.6) | M4: Release | N4: Parent valid | O4: Comment
A5: SW-REQ-001 | B5: Frame reception | C5: The firmware shall receive frames with the APK5 interrupt state machine (WAIT_SOF, WAIT_CMD, WAIT_DATA, 50 ms inter-byte timeout, error re-arm) and post them to QueueFrame. | D5: Functional | E5: SWC-ISR, SWC-QUEUE | F5: SYS-REQ-008, SYS-REQ-010 | G5: Reuse of the validated APK5 link layer. | H5: High | I5: Accepted | J5: Test | K5: PING answered; partial frame dropped. | L5: TC-01 | M5: R1.0 | N5: =IF(ISNUMBER(MATCH(LEFT(F5,11),'System Requirements'!$A$5:$A$15,0)),"OK","MISSING") -> OK
A6: SW-REQ-002 | B6: Local link commands | C6: The LinkLayer task shall answer PING (0x01) and GET_STATUS (0x21) itself, in every system state. | D6: Functional | E6: SWC-LL | F6: SYS-REQ-008 | G6: Diagnostics must work even while the SystemTask is suspended. | H6: High | I6: Accepted | J6: Test | K6: PING and GET_STATUS answered in IDLE, READY, RUN and with the door open. | L6: TC-01, TC-10 | M6: R1.0 | N6: =IF(ISNUMBER(MATCH(LEFT(F6,11),'System Requirements'!$A$5:$A$15,0)),"OK","MISSING") -> OK
A7: SW-REQ-003 | B7: GET_STATUS value | C7: The GET_STATUS response DATA shall be the SystemTask state in bits 0..3 (0 IDLE_STATE, 1 READY_STATE, 2 RUN_STATE) and bit 7 set when the SensorTask is in ERROR_STATE. | D7: Interface | E7: SWC-LL | F7: SYS-REQ-004 | G7: GUI synchronises on connection. | H7: Medium | I7: Accepted | J7: Test | K7: IDLE: A1 00; READY: A1 01; RUN: A1 02; RUN + door open: A1 82. | L7: TC-10 | M7: R1.0 | N7: =IF(ISNUMBER(MATCH(LEFT(F7,11),'System Requirements'!$A$5:$A$15,0)),"OK","MISSING") -> OK
A8: SW-REQ-004 | B8: Admission control | C8: While the SystemTask is in RUN_STATE (running or suspended by the door), the LinkLayer task shall answer CFG_PROGRAM, CFG_TEMP, CFG_SPIN and START_CYCLE with 0xE3 (BUSY) without forwarding them. | D8: Functional | E8: SWC-LL | F8: SYS-REQ-007 | G8: Immediate answer even when SystemTask is suspended. | H8: High | I8: Accepted | J8: Test | K8: Config and start in RUN_STATE, running or suspended -> E3. | L8: TC-07 | M8: R1.0 | N8: =IF(ISNUMBER(MATCH(LEFT(F8,11),'System Requirements'!$A$5:$A$15,0)),"OK","MISSING") -> OK
A9: SW-REQ-005 | B9: Command forwarding | C9: In IDLE_STATE and READY_STATE, the LinkLayer task shall forward application commands to the SystemTask through QueueCmd (4 frames); if QueueCmd is full it shall answer 0xE3. | D9: Functional | E9: SWC-LL, SWC-CMDQ | F9: SYS-REQ-008 | G9: SystemTask owns the application state. | H9: High | I9: Accepted | J9: Test | K9: Configuration frames answered by SystemTask. | L9: TC-02 | M9: R1.0 | N9: =IF(ISNUMBER(MATCH(LEFT(F9,11),'System Requirements'!$A$5:$A$15,0)),"OK","MISSING") -> OK
A10: SW-REQ-006 | B10: Unknown command | C10: Any command not defined in the interface specification shall be answered with 0xE1 (BAD_CMD). | D10: Functional | E10: SWC-LL | F10: SYS-REQ-008 | G10: Protocol errors reported. | H10: Medium | I10: Accepted | J10: Test | K10: AA 42 00 -> AA C2 E1 | L10: TC-11 | M10: R1.0 | N10: =IF(ISNUMBER(MATCH(LEFT(F10,11),'System Requirements'!$A$5:$A$15,0)),"OK","MISSING") -> OK
A11: SW-REQ-007 | B11: CFG_PROGRAM | C11: CFG_PROGRAM (0x10) with DATA 0..3 shall store the program and answer 0x00; other values shall answer 0xE2 and keep the previous value. | D11: Functional | E11: SWC-SYS | F11: SYS-REQ-001 | G11: Program selection. | H11: High | I11: Accepted | J11: Test | K11: AA 10 01 -> AA 90 00; AA 10 04 -> AA 90 E2 | L11: TC-02, TC-03 | M11: R1.0 | N11: =IF(ISNUMBER(MATCH(LEFT(F11,11),'System Requirements'!$A$5:$A$15,0)),"OK","MISSING") -> OK
A12: SW-REQ-008 | B12: CFG_TEMP | C12: CFG_TEMP (0x11) with DATA in {20, 30, 40, 60, 90} shall store the temperature and answer 0x00; other values shall answer 0xE2. | D12: Functional | E12: SWC-SYS | F12: SYS-REQ-001 | G12: Only real machine temperatures. | H12: High | I12: Accepted | J12: Test | K12: AA 11 28 -> AA 91 00; AA 11 2D -> AA 91 E2 | L12: TC-02, TC-03 | M12: R1.0 | N12: =IF(ISNUMBER(MATCH(LEFT(F12,11),'System Requirements'!$A$5:$A$15,0)),"OK","MISSING") -> OK
A13: SW-REQ-009 | B13: CFG_SPIN | C13: CFG_SPIN (0x12) with DATA 4..14 (x 100 rpm) shall store the spin speed and answer 0x00; other values shall answer 0xE2. | D13: Functional | E13: SWC-SYS | F13: SYS-REQ-001 | G13: Spin range 400..1400 rpm. | H13: High | I13: Accepted | J13: Test | K13: AA 12 0A -> AA 92 00; AA 12 03 -> AA 92 E2 | L13: TC-02, TC-03 | M13: R1.0 | N13: =IF(ISNUMBER(MATCH(LEFT(F13,11),'System Requirements'!$A$5:$A$15,0)),"OK","MISSING") -> OK
A14: SW-REQ-010 | B14: IDLE_STATE to READY_STATE | C14: In IDLE_STATE the SystemTask shall wait for configuration frames; when program, temperature and spin have each been accepted, it shall switch on the orange LED and go to READY_STATE. | D14: Functional | E14: SWC-SYS | F14: SYS-REQ-001, SYS-REQ-007 | G14: Start allowed only with a full configuration. | H14: High | I14: Accepted | J14: Test | K14: GET_STATUS 00 before, 01 after the third accepted parameter. | L14: TC-02 | M14: R1.0 | N14: =IF(ISNUMBER(MATCH(LEFT(F14,11),'System Requirements'!$A$5:$A$15,0)),"OK","MISSING") -> OK
A15: SW-REQ-011 | B15: Start without configuration | C15: START_CYCLE (0x20) received in IDLE_STATE shall be answered 0xE4 (NOT_CONFIGURED); the state stays IDLE_STATE. | D15: Functional | E15: SWC-SYS | F15: SYS-REQ-007 | G15: Rule: no start without configuration. | H15: High | I15: Accepted | J15: Test | K15: After reset: AA 20 00 -> AA A0 E4 | L15: TC-04 | M15: R1.0 | N15: =IF(ISNUMBER(MATCH(LEFT(F15,11),'System Requirements'!$A$5:$A$15,0)),"OK","MISSING") -> OK
A16: SW-REQ-012 | B16: Start with door open | C16: START_CYCLE in READY_STATE while the SensorTask is in ERROR_STATE shall be answered 0xE5 (DOOR_OPEN); the state stays READY_STATE. | D16: Functional | E16: SWC-SYS | F16: SYS-REQ-007 | G16: Safety rule. | H16: High | I16: Accepted | J16: Test | K16: Door open: AA 20 00 -> AA A0 E5 | L16: TC-08 | M16: R1.0 | N16: =IF(ISNUMBER(MATCH(LEFT(F16,11),'System Requirements'!$A$5:$A$15,0)),"OK","MISSING") -> OK
... A43: SW-REQ-039 | B43: SystemTask state machine | C43: The SystemTask shall implement the states IDLE_STATE (wait for configuration), READY_STATE (wait for START) and RUN_STATE (execute the cycle), with the transitions IDLE->READY on complete configuration, READY->RUN on accepted START and RUN->READY at the end of the cycle. | D43: Functional | E43: SWC-SYS | F43: SYS-REQ-001, SYS-REQ-002, SYS-REQ-003, SYS-REQ-007 | G43: Explicit, testable application behaviour. | H43: High | I43: Accepted | J43: Test | K43: GET_STATUS 00 -> 01 -> 02 -> 01 along TC-02 and TC-05. | L43: TC-02, TC-05, TC-10 | M43: R1.0 | N43: =IF(ISNUMBER(MATCH(LEFT(F43,11),'System Requirements'!$A$5:$A$15,0)),"OK","MISSING") -> OK

Sheet Interface Spec
A1: Interface Specification - UART frames
A2: APK6-SRS-001 | Version 1.1 | USART2, 115200 baud, 8N1 - requests, responses and events
A4: Frame
A5: Byte | B5: Field | C5: Request (Host -> STM32) | D5: STM32 -> Host | E5: Requirement
A6: 0 | B6: SOF | C6: 0xAA | D6: 0xAA | E6: SW-REQ-001
A7: 1 | B7: CMD | C7: Request code | D7: Request CMD OR 0x80, or event code 0x30..0x34 | E7: SW-REQ-036
A8: 2 | B8: DATA | C8: Parameter | D8: Status, value or event data | E8: SW-REQ-036
A10: Requests (answered with CMD | 0x80)
A11: CMD | B11: Name | C11: Request DATA | D11: Response DATA | E11: Accepted in | F11: Requirement
A12: 0x01 | B12: PING | C12: Any | D12: Same value | E12: Any | F12: SW-REQ-002
A13: 0x10 | B13: CFG_PROGRAM | C13: 0 Cotton, 1 Synthetic, 2 Wool, 3 Quick | D13: 00 / E2 / E3 | E13: IDLE, READY | F13: SW-REQ-007
A14: 0x11 | B14: CFG_TEMP | C14: 20, 30, 40, 60, 90 | D14: 00 / E2 / E3 | E14: IDLE, READY | F14: SW-REQ-008
A15: 0x12 | B15: CFG_SPIN | C15: 4..14 (x 100 rpm) | D15: 00 / E2 / E3 | E15: IDLE, READY | F15: SW-REQ-009
A16: 0x20 | B16: START_CYCLE | C16: Ignored | D16: 00 / E4 (in IDLE) / E5 / E3 | E16: READY | F16: SW-REQ-011..013
A17: 0x21 | B17: GET_STATUS | C17: Ignored | D17: bits 0..3: 0 IDLE, 1 READY, 2 RUN; bit 7: door ERROR_STATE | E17: Any | F17: SW-REQ-003
A18: other | B18: - | C18: Any | D18: E1 | E18: Any | F18: SW-REQ-006
A20: Events (sent by the STM32 without request)
A21: CMD | B21: Name | C21: DATA | D21: When | E21: Requirement
A22: 0x30 | B22: EVT_STEP | C22: Step 1..6 entered | D22: Step entry | E22: SW-REQ-014
A23: 0x31 | B23: EVT_PROGRESS | C23: Step progress 0..100 % | D23: Every 200 ms in RUN | E23: SW-REQ-016
A24: 0x32 | B24: EVT_DONE | C24: 0 | D24: End of step 6 | E24: SW-REQ-017
A25: 0x33 | B25: EVT_DOOR | C25: 1 open, 0 closed | D25: Each door press | E25: SW-REQ-020
A26: 0x34 | B26: EVT_ERROR | C26: 0x01 door open during cycle | D26: Door opened in RUN | E26: SW-REQ-021
A28: Status codes
A29: Code | B29: Name | C29: Meaning
A30: 0x00 | B30: OK | C30: Command executed
A31: 0xE1 | B31: BAD_CMD | C31: Unknown command
A32: 0xE2 | B32: BAD_DATA | C32: Parameter out of range
A33: 0xE3 | B33: BUSY | C33: SystemTask in RUN_STATE (running or suspended)
A34: 0xE4 | B34: NOT_CONFIGURED | C34: START in IDLE_STATE
A35: 0xE5 | B35: DOOR_OPEN | C35: START while the SensorTask is in ERROR_STATE

Sheet SW Components
A1: Software Components (SWE.2)
A2: APK6-SRS-001 | Version 1.1 | Elements of the software architecture
A4: Component ID | B4: Name | C4: Implementation | D4: File | E4: Execution context | F4: Responsibility | G4: # SW req allocated
A5: SWC-ISR | B5: UART RX callback | C5: HAL_UART_RxCpltCallback, HAL_UART_ErrorCallback | D5: Core/Src/apk6.c | E5: Interrupt | F5: Byte reception, frame state machine, timeout. | G5: =COUNTIF('SW Requirements'!$E$5:$E$200,"*"&A5&"*") -> 1
A6: SWC-QUEUE | B6: QueueFrame | C6: FreeRTOS queue, 8 x Frame_t | D6: Core/Src/apk6.c | E6: Kernel object | F6: Frames from ISR to LinkLayer. | G6: =COUNTIF('SW Requirements'!$E$5:$E$200,"*"&A6&"*") -> 1
A7: SWC-LL | B7: LinkLayer task | C7: LinkLayer(), prio 3 | D7: Core/Src/apk6.c | E7: Task | F7: PING, GET_STATUS, admission control, forwarding. | G7: =COUNTIF('SW Requirements'!$E$5:$E$200,"*"&A7&"*") -> 6
A8: SWC-CMDQ | B8: QueueCmd | C8: FreeRTOS queue, 4 x Frame_t | D8: Core/Src/apk6.c | E8: Kernel object | F8: Application commands to SystemTask. | G8: =COUNTIF('SW Requirements'!$E$5:$E$200,"*"&A8&"*") -> 1
A9: SWC-SYS | B9: SystemTask | C9: SystemTask(), ApplyConfig(), RunCycle(), prio 2 | D9: Core/Src/apk6.c | E9: Task | F9: IDLE_STATE / READY_STATE / RUN_STATE machine, configuration, cycle timing, events. | G9: =COUNTIF('SW Requirements'!$E$5:$E$200,"*"&A9&"*") -> 16
A10: SWC-SEN | B10: SensorTask + EXTI | C10: SensorTask(), HAL_GPIO_EXTI_Callback, SemDoor, prio 4 | D10: Core/Src/apk6.c | E10: Task + interrupt | F10: NO_ERROR_STATE / ERROR_STATE machine, debounce, suspend / resume of SystemTask, door events. | G10: =COUNTIF('SW Requirements'!$E$5:$E$200,"*"&A10&"*") -> 9
A11: SWC-TX | B11: Frame transmitter | C11: SendFrame() | D11: Core/Src/apk6.c | E11: Task context | F11: 3-byte frames under xUartMutex. | G11: =COUNTIF('SW Requirements'!$E$5:$E$200,"*"&A11&"*") -> 2
A12: SWC-CFG | B12: Configuration | C12: main.h, stm32f4xx_hal_msp.c, log.c | D12: Core/ | E12: Static | F12: Lab selection, UART init, printf mutex. | G12: =COUNTIF('SW Requirements'!$E$5:$E$200,"*"&A12&"*") -> 2
A13: SWC-GUI | B13: Host GUI | C13: MainWindow, MachineView | D13: tools/apk6_gui.py | E13: PyQt5 main thread | F13: Configuration, start, live display, log. | G13: =COUNTIF('SW Requirements'!$E$5:$E$200,"*"&A13&"*") -> 7
A14: SWC-RDR | B14: Host serial reader | C14: SerialReader (QThread) | D14: tools/apk6_gui.py | E14: Worker thread | F14: Host framing state machine. | G14: =COUNTIF('SW Requirements'!$E$5:$E$200,"*"&A14&"*") -> 1
A15: SWC-SIM | B15: Board simulator | C15: SimBoard | D15: tools/apk6_proto.py | E15: Python threads | F15: Software twin of apk6.c. | G15: =COUNTIF('SW Requirements'!$E$5:$E$200,"*"&A15&"*") -> 1

Sheet Test Specification
A1: Software Qualification Test Specification (SWE.6)
A2: APK6-SRS-001 | Version 1.1 | Fill in Result, Date and Tester after each run
A4: Test ID | B4: Title | C4: Method | D4: Precondition | E4: Steps | F4: Expected result | G4: Verifies | H4: Result | I4: Date | J4: Tester | K4: Remark
A5: TC-01 | B5: Link layer | C5: Test | D5: Board running APK6, GUI connected | E5: Send PING 0x55; send AA 01 then wait 200 ms then AA 01 20. | F5: AA 81 55; only AA 81 20 for the second pattern. | G5: SW-REQ-001, SW-REQ-002, SW-REQ-036 | H5: Not run
A6: TC-02 | B6: Valid configuration | C6: Test | D6: After reset, IDLE | E6: Select Wool, 40 C, 1000 rpm; press Send configuration. | F6: AA 90 00, AA 91 00, AA 92 00; READY_STATE; orange LED on; GUI shows READY. | G6: SW-REQ-005, SW-REQ-007, SW-REQ-008, SW-REQ-009, SW-REQ-010, SW-REQ-030, SW-REQ-039 | H6: Not run
A7: TC-03 | B7: Invalid parameters | C7: Test | D7: IDLE | E7: Send AA 10 04, AA 11 2D, AA 12 03, AA 12 0F. | F7: Each answered with E2; state unchanged. | G7: SW-REQ-007, SW-REQ-008, SW-REQ-009 | H7: Not run
A8: TC-04 | B8: Start without configuration | C8: Test | D8: After reset, IDLE | E8: Press START CYCLE. | F8: AA A0 E4; GUI shows 'send a configuration first'; state IDLE. | G8: SW-REQ-011, SW-REQ-034 | H8: Not run
A9: TC-05 | B9: Complete cycle | C9: Test | D9: Configured, door closed | E9: Press START CYCLE and wait for the end. | F9: AA A0 00; EVT_STEP 1..6 in order; EVT_DONE after about 60 s; green LED blinks, blue LED at the end. | G9: SW-REQ-013, SW-REQ-014, SW-REQ-017, SW-REQ-028, SW-REQ-031, SW-REQ-036, SW-REQ-039 | H9: Not run
A10: TC-06 | B10: Timing and live display | C10: Test | D10: Configured | E10: Start a cycle, record the event time stamps. | F10: Each step 10 s +/- 0.3 s; EVT_PROGRESS every 200 ms; GUI bars follow. | G10: SW-REQ-015, SW-REQ-016, SW-REQ-032 | H10: Not run
A11: TC-07 | B11: Commands during cycle | C11: Test | D11: Cycle running | E11: Press Send configuration, then START CYCLE; repeat with the door open (cycle suspended). | F11: All answered E3; cycle not disturbed. | G11: SW-REQ-004, SW-REQ-034 | H11: Not run
A12: TC-08 | B12: Door open | C12: Test | D12: Cycle running in step 3 | E12: Press B1 once; wait 5 s. Then in READY press B1 and START. | F12: EVT_DOOR 1 + EVT_ERROR 01; red LED; banner; no event for 5 s; GET_STATUS = 82. In READY: only EVT_DOOR 1, START -> E5. | G12: SW-REQ-012, SW-REQ-019, SW-REQ-020, SW-REQ-021, SW-REQ-022, SW-REQ-024, SW-REQ-028, SW-REQ-033 | H12: Not run
A13: TC-09 | B13: Door close and resume | C13: Test | D13: Cycle suspended (ERROR_STATE) | E13: Press B1 again. | F13: EVT_DOOR 0; banner cleared; next EVT_PROGRESS continues the same step; total time = 60 s + pause. | G13: SW-REQ-023, SW-REQ-033 | H13: Not run
A14: TC-10 | B14: GET_STATUS | C14: Test | D14: Connected | E14: Send GET_STATUS after reset, after configuration, during RUN, with the door open during RUN; reconnect GUI during RUN. | F14: DATA 00, 01, 02, 82; GUI shows RUNNING / PAUSED after reconnect. | G14: SW-REQ-002, SW-REQ-003, SW-REQ-037, SW-REQ-039 | H14: Not run
A15: TC-11 | B15: Unknown command | C15: Test | D15: Connected | E15: Send AA 42 00. | F15: AA C2 E1. | G15: SW-REQ-006 | H15: Not run
A16: TC-12 | B16: Door stress | C16: Test | D16: Cycle running | E16: Press B1 20 times quickly while the cycle runs. | F16: Alternating EVT_DOOR, no corrupted frame, no deadlock, cycle ends normally. | G16: SW-REQ-019, SW-REQ-025, SW-REQ-026 | H16: Not run
... A18: TC-14 | B18: Code review and inspection | C18: Review | D18: apk6.c | E18: Check priorities, mutex taken before vTaskSuspend, QueueCmd drained in RUN, APK6 guard. | F18: All checklist items OK. | G18: SW-REQ-018, SW-REQ-025, SW-REQ-027, SW-REQ-029 | H18: Not run

Sheet Traceability
A1: Traceability Matrix SW Requirement x Test Case
A2: APK6-SRS-001 | Version 1.1 | X = test case verifies the requirement (bidirectional, ASPICE SWE.6 BP5)
A4: SW req | B4: Title | C4: TC-01 | D4: TC-02 | E4: TC-03 | F4: TC-04 | G4: TC-05 | H4: TC-06 | I4: TC-07 | J4: TC-08 | K4: TC-09 | L4: TC-10 | M4: TC-11 | N4: TC-12 | O4: TC-13 | P4: TC-14 | Q4: # tests | R4: Coverage
A5: SW-REQ-001 | B5: Frame reception | C5: X | Q5: =COUNTIF(C5:P5,"X") -> 1 | R5: =IF(Q5>0,"Covered","NOT COVERED") -> Covered
A6: SW-REQ-002 | B6: Local link commands | C6: X | L6: X | Q6: =COUNTIF(C6:P6,"X") -> 2 | R6: =IF(Q6>0,"Covered","NOT COVERED") -> Covered
A7: SW-REQ-003 | B7: GET_STATUS value | L7: X | Q7: =COUNTIF(C7:P7,"X") -> 1 | R7: =IF(Q7>0,"Covered","NOT COVERED") -> Covered
A8: SW-REQ-004 | B8: Admission control | I8: X | Q8: =COUNTIF(C8:P8,"X") -> 1 | R8: =IF(Q8>0,"Covered","NOT COVERED") -> Covered
A9: SW-REQ-005 | B9: Command forwarding | D9: X | Q9: =COUNTIF(C9:P9,"X") -> 1 | R9: =IF(Q9>0,"Covered","NOT COVERED") -> Covered
A10: SW-REQ-006 | B10: Unknown command | M10: X | Q10: =COUNTIF(C10:P10,"X") -> 1 | R10: =IF(Q10>0,"Covered","NOT COVERED") -> Covered
A11: SW-REQ-007 | B11: CFG_PROGRAM | D11: X | E11: X | Q11: =COUNTIF(C11:P11,"X") -> 2 | R11: =IF(Q11>0,"Covered","NOT COVERED") -> Covered
A12: SW-REQ-008 | B12: CFG_TEMP | D12: X | E12: X | Q12: =COUNTIF(C12:P12,"X") -> 2 | R12: =IF(Q12>0,"Covered","NOT COVERED") -> Covered
A13: SW-REQ-009 | B13: CFG_SPIN | D13: X | E13: X | Q13: =COUNTIF(C13:P13,"X") -> 2 | R13: =IF(Q13>0,"Covered","NOT COVERED") -> Covered
A14: SW-REQ-010 | B14: IDLE_STATE to READY_STATE | D14: X | Q14: =COUNTIF(C14:P14,"X") -> 1 | R14: =IF(Q14>0,"Covered","NOT COVERED") -> Covered
A15: SW-REQ-011 | B15: Start without configuration | F15: X | Q15: =COUNTIF(C15:P15,"X") -> 1 | R15: =IF(Q15>0,"Covered","NOT COVERED") -> Covered
A16: SW-REQ-012 | B16: Start with door open | J16: X | Q16: =COUNTIF(C16:P16,"X") -> 1 | R16: =IF(Q16>0,"Covered","NOT COVERED") -> Covered
A17: SW-REQ-013 | B17: Start accepted | G17: X | Q17: =COUNTIF(C17:P17,"X") -> 1 | R17: =IF(Q17>0,"Covered","NOT COVERED") -> Covered
A18: SW-REQ-014 | B18: Cycle steps | G18: X | Q18: =COUNTIF(C18:P18,"X") -> 1 | R18: =IF(Q18>0,"Covered","NOT COVERED") -> Covered
A19: SW-REQ-015 | B19: Step duration | H19: X | Q19: =COUNTIF(C19:P19,"X") -> 1 | R19: =IF(Q19>0,"Covered","NOT COVERED") -> Covered
A20: SW-REQ-016 | B20: Progress event | H20: X | Q20: =COUNTIF(C20:P20,"X") -> 1 | R20: =IF(Q20>0,"Covered","NOT COVERED") -> Covered
A21: SW-REQ-017 | B21: End of cycle | G21: X | Q21: =COUNTIF(C21:P21,"X") -> 1 | R21: =IF(Q21>0,"Covered","NOT COVERED") -> Covered
A22: SW-REQ-018 | B22: Late commands | P22: X | Q22: =COUNTIF(C22:P22,"X") -> 1 | R22: =IF(Q22>0,"Covered","NOT COVERED") -> Covered
A23: SW-REQ-019 | B23: Door sensor acquisition | J23: X | N23: X | Q23: =COUNTIF(C23:P23,"X") -> 2 | R23: =IF(Q23>0,"Covered","NOT COVERED") -> Covered
A24: SW-REQ-020 | B24: SensorTask state machine | J24: X | Q24: =COUNTIF(C24:P24,"X") -> 1 | R24: =IF(Q24>0,"Covered","NOT COVERED") -> Covered
A25: SW-REQ-021 | B25: Suspend on door open | J25: X | Q25: =COUNTIF(C25:P25,"X") -> 1 | R25: =IF(Q25>0,"Covered","NOT COVERED") -> Covered
A26: SW-REQ-022 | B26: Frozen while paused | J26: X | Q26: =COUNTIF(C26:P26,"X") -> 1 | R26: =IF(Q26>0,"Covered","NOT COVERED") -> Covered
A27: SW-REQ-023 | B27: Resume on door close | K27: X | Q27: =COUNTIF(C27:P27,"X") -> 1 | R27: =IF(Q27>0,"Covered","NOT COVERED") -> Covered
A28: SW-REQ-024 | B28: Door outside a cycle | J28: X | Q28: =COUNTIF(C28:P28,"X") -> 1 | R28: =IF(Q28>0,"Covered","NOT COVERED") -> Covered
A29: SW-REQ-025 | B29: Safe suspension | N29: X | P29: X | Q29: =COUNTIF(C29:P29,"X") -> 2 | R29: =IF(Q29>0,"Covered","NOT COVERED") -> Covered
A30: SW-REQ-026 | B30: UART mutual exclusion | N30: X | Q30: =COUNTIF(C30:P30,"X") -> 1 | R30: =IF(Q30>0,"Covered","NOT COVERED") -> Covered
A31: SW-REQ-027 | B31: Task priorities | P31: X | Q31: =COUNTIF(C31:P31,"X") -> 1 | R31: =IF(Q31>0,"Covered","NOT COVERED") -> Covered
A32: SW-REQ-028 | B32: LED indication | G32: X | J32: X | Q32: =COUNTIF(C32:P32,"X") -> 2 | R32: =IF(Q32>0,"Covered","NOT COVERED") -> Covered
A33: SW-REQ-029 | B33: Build selection | P33: X | Q33: =COUNTIF(C33:P33,"X") -> 1 | R33: =IF(Q33>0,"Covered","NOT COVERED") -> Covered
A34: SW-REQ-030 | B34: Configuration panel | D34: X | Q34: =COUNTIF(C34:P34,"X") -> 1 | R34: =IF(Q34>0,"Covered","NOT COVERED") -> Covered
A35: SW-REQ-031 | B35: Start button | G35: X | Q35: =COUNTIF(C35:P35,"X") -> 1 | R35: =IF(Q35>0,"Covered","NOT COVERED") -> Covered
A36: SW-REQ-032 | B36: Live cycle display | H36: X | Q36: =COUNTIF(C36:P36,"X") -> 1 | R36: =IF(Q36>0,"Covered","NOT COVERED") -> Covered
A37: SW-REQ-033 | B37: Door error display | J37: X | K37: X | Q37: =COUNTIF(C37:P37,"X") -> 2 | R37: =IF(Q37>0,"Covered","NOT COVERED") -> Covered
A38: SW-REQ-034 | B38: Refusal display | F38: X | I38: X | Q38: =COUNTIF(C38:P38,"X") -> 2 | R38: =IF(Q38>0,"Covered","NOT COVERED") -> Covered
A39: SW-REQ-035 | B39: GUI guard option | O39: X | Q39: =COUNTIF(C39:P39,"X") -> 1 | R39: =IF(Q39>0,"Covered","NOT COVERED") -> Covered
A40: SW-REQ-036 | B40: Host frame parser | C40: X | G40: X | Q40: =COUNTIF(C40:P40,"X") -> 2 | R40: =IF(Q40>0,"Covered","NOT COVERED") -> Covered
A41: SW-REQ-037 | B41: Status on connect | L41: X | Q41: =COUNTIF(C41:P41,"X") -> 1 | R41: =IF(Q41>0,"Covered","NOT COVERED") -> Covered
...

Sheet Dashboard
A1: Dashboard
A2: APK6-SRS-001 | Version 1.1 | All values are formulas - they update when the sheets change
A4: Total SW requirements | B4: =COUNTA('SW Requirements'!$A$5:$A$43) -> 39
A5: Total system requirements | B5: =COUNTA('System Requirements'!$A$5:$A$15) -> 11
A6: Total test cases | B6: =COUNTA('Test Specification'!$A$5:$A$18) -> 14
A7: SW reqs covered by a test | B7: =COUNTIF(Traceability!$R$5:$R$43,"Covered") -> 39 | C7: =IF(B4=0,0,B7/B4) -> 1
A8: SYS reqs without SW req | B8: =COUNTIF('System Requirements'!$I$5:$I$15,0) -> 0
A9: SW reqs with invalid parent | B9: =COUNTIF('SW Requirements'!$N$5:$N$43,"MISSING") -> 0
A11: SW requirements by status
A12: Status | B12: Count | C12: Share
A13: Draft | B13: =COUNTIF('SW Requirements'!$I$5:$I$43,A13) -> 0 | C13: =IF($B$4=0,0,B13/$B$4) -> 0
A14: In review | B14: =COUNTIF('SW Requirements'!$I$5:$I$43,A14) -> 0 | C14: =IF($B$4=0,0,B14/$B$4) -> 0
A15: Accepted | B15: =COUNTIF('SW Requirements'!$I$5:$I$43,A15) -> 39 | C15: =IF($B$4=0,0,B15/$B$4) -> 1
A16: Rejected | B16: =COUNTIF('SW Requirements'!$I$5:$I$43,A16) -> 0 | C16: =IF($B$4=0,0,B16/$B$4) -> 0
A17: Deferred | B17: =COUNTIF('SW Requirements'!$I$5:$I$43,A17) -> 0 | C17: =IF($B$4=0,0,B17/$B$4) -> 0
A20: SW requirements by type
A21: Type | B21: Count | C21: Share
A22: Functional | B22: =COUNTIF('SW Requirements'!$D$5:$D$43,A22) -> 32 | C22: =IF($B$4=0,0,B22/$B$4) -> 0.82051282
A23: Non-functional | B23: =COUNTIF('SW Requirements'!$D$5:$D$43,A23) -> 2 | C23: =IF($B$4=0,0,B23/$B$4) -> 0.051282051
A24: Interface | B24: =COUNTIF('SW Requirements'!$D$5:$D$43,A24) -> 1 | C24: =IF($B$4=0,0,B24/$B$4) -> 0.025641026
A25: Performance | B25: =COUNTIF('SW Requirements'!$D$5:$D$43,A25) -> 2 | C25: =IF($B$4=0,0,B25/$B$4) -> 0.051282051
A26: Constraint | B26: =COUNTIF('SW Requirements'!$D$5:$D$43,A26) -> 2 | C26: =IF($B$4=0,0,B26/$B$4) -> 0.051282051
A29: SW requirements by verification method
A30: Method | B30: Count | C30: Share
A31: Test | B31: =COUNTIF('SW Requirements'!$J$5:$J$43,A31) -> 34 | C31: =IF($B$4=0,0,B31/$B$4) -> 0.87179487
A32: Analysis | B32: =COUNTIF('SW Requirements'!$J$5:$J$43,A32) -> 0 | C32: =IF($B$4=0,0,B32/$B$4) -> 0
A33: Review | B33: =COUNTIF('SW Requirements'!$J$5:$J$43,A33) -> 2 | C33: =IF($B$4=0,0,B33/$B$4) -> 0.051282051
A34: Inspection | B34: =COUNTIF('SW Requirements'!$J$5:$J$43,A34) -> 2 | C34: =IF($B$4=0,0,B34/$B$4) -> 0.051282051
A35: Demonstration | B35: =COUNTIF('SW Requirements'!$J$5:$J$43,A35) -> 1 | C35: =IF($B$4=0,0,B35/$B$4) -> 0.025641026
A38: Test results
A39: Result | B39: Count | C39: Share
A40: Not run | B40: =COUNTIF('Test Specification'!$H$5:$H$18,A40) -> 14 | C40: =IF($B$6=0,0,B40/$B$6) -> 1
A41: Passed | B41: =COUNTIF('Test Specification'!$H$5:$H$18,A41) -> 0 | C41: =IF($B$6=0,0,B41/$B$6) -> 0
A42: Failed | B42: =COUNTIF('Test Specification'!$H$5:$H$18,A42) -> 0 | C42: =IF($B$6=0,0,B42/$B$6) -> 0
A43: Blocked | B43: =COUNTIF('Test Specification'!$H$5:$H$18,A43) -> 0 | C43: =IF($B$6=0,0,B43/$B$6) -> 0
